Workbook

Sheet FRONT
Y1: SF-10 for SHS | AC1: NOTES
A2: REPUBLIC OF THE PHILIPPINES
A3: DEPARTMENT OF EDUCATION
A4: SENIOR HIGH SCHOOL LEARNER'S PERMANENT RECORD
A5: LEARNER'S INFORMATION
A7: Last Name: | I7: First Name: | Q7: Middle Name: | X7: Extension:
A8: LRN: | I8: Date of Birth: | O8: Sex: | V8: Date of SHS Admission:
K9: MM / DD / YYYY | W9: MM / DD / YYYY
A10: ELIGIBILITY FOR SHS ENROLMENT | AC10: selected
B12: High School Completer* | G12: Gen. Ave: | K12: Junior High School Completer | Q12: Gen. Ave: | AC12: 6
B13: Date of Graduation/Completion: | K13: Name of School: | U13: School Add.:
G14: MM / DD / YYYY
B15: PEPT Passer** | G15: Rating: | K15: ALS A&E Passer*** | O15: Rating: | S15: Others (Pls.Specify):
B16: Date of Examination/Assessment: | K16: Name & Address of CLC:
G17: MM / DD / YYYY | O17: (Community Learning Center)
A18: *High School Completers are students who graduated from secondary school under the old curriculum | K18: ***ALS A&E - Alternative Learning System Accreditation and Equivalency Test for JHS
A19: **PEPT - Philippine Educational Placement Test for JHS
A20: SCHOLASTIC RECORD
A22: SCHOOL: | M22: SCHOOL ID: | R22: GRADE LEVEL: | S22: 11 | V22: SECTION: | AA22: FIRST SEMESTER / FIRST SEMESTER / FIRST SEMESTER / FIRST SEMESTER / FIRST SEMESTER
A23: TRACK: | R23: SCHOOL YEAR: | V23: SEM: | W23: FIRST
A25: TRACK | D25: SUBJECTS | R25: QUARTERLY GRADE | T25: 1ST SEMESTRAL GRADE | W25: REMARK
T26: GEN. AVE. | U26: ACTION TAKEN
A27: Core/Academic/TechPro | D27: Specific core or elective subject | R27: Q1 | S27: Q2 | W27: Final Grade Computation
A28: 1 | B28: CORE | D28: Effective Communication & Mabisang Komunikasyon | R28: =IF(AND(R29<>"",R30<>""),ROUND(AVERAGE(R29:R30),),"") | S28: =IF(AND(S29<>"",S30<>""),ROUND(AVERAGE(S29:S30),),"") | W28: The General Average / Final Grade is the average of four (4) quarterly grades.
A29: 1A | B29: CORE | D29: Effective Communication
A30: 1B | B30: CORE | D30: Mabisang Komunikasyon
A31: 2 | B31: CORE | D31: General Mathematics
A32: 3 | B32: CORE | D32: General Science
A33: 4 | B33: CORE | D33: Life and Career Skills
A34: 5 | B34: CORE | D34: Pag-aaral ng Kasaysayan at Lipunang Pilipino | AD34: Listed | AE34: New | AF34: Quarters
A35: 6 | T35: =IF(AF35=2,IF(COUNTA(R35:S35)=2,ROUND(AVERAGE(R35:S35),0),""),"") | U35: =IF(T35<>"",IF(T35<75,"FAILED","PASSED"),"") | W35: =_xlfn.IFNA(_xlfn.XLOOKUP(AF35,HELPER_SUBJECTS!$I$13:$I$14,HELPER_SUBJECTS!$J$13:$J$14),"") | AC35: =IF(B35="ACADEMIC",HELPER_SUBJECTS!$S$4,IF(B35="TECHPRO",HELPER_SUBJECTS!$T$4,"")) | AD35: =_xlfn.IFNA(_xlfn.XLOOKUP(D35,HELPER_SUBJECTS!D:D,HELPER_SUBJECTS!F:F),0) -> 0 | AE35: =_xlfn.IFNA(IF(D35<>"",_xlfn.XLOOKUP(D35,ANNEX!$F$52:$F$61,ANNEX!$H$52:$H$61),0),0) -> 0 | AF35: =IF(AND(AD35>0,AE35=0),AD35,IF(AND(AE35>0,AD35=0),AE35,0)) -> 0
A36: 7 | T36: =IF(AF36=2,IF(COUNTA(R36:S36)=2,ROUND(AVERAGE(R36:S36),0),""),"") | U36: =IF(T36<>"",IF(T36<75,"FAILED","PASSED"),"") | W36: =_xlfn.IFNA(_xlfn.XLOOKUP(AD36,HELPER_SUBJECTS!$I$13:$I$14,HELPER_SUBJECTS!$J$13:$J$14),"") | AC36: =IF(B36="ACADEMIC",HELPER_SUBJECTS!$S$4,IF(B36="TECHPRO",HELPER_SUBJECTS!$T$4,"")) | AD36: =_xlfn.IFNA(_xlfn.XLOOKUP(D36,HELPER_SUBJECTS!D:D,HELPER_SUBJECTS!F:F),0) -> 0 | AE36: =_xlfn.IFNA(IF(D36<>"",_xlfn.XLOOKUP(D36,ANNEX!$F$52:$F$61,ANNEX!$H$52:$H$61),0),0) -> 0 | AF36: =IF(AND(AD36>0,AE36=0),AD36,IF(AND(AE36>0,AD36=0),AE36,0)) -> 0
A37: 8 | T37: =IF(AF37=2,IF(COUNTA(R37:S37)=2,ROUND(AVERAGE(R37:S37),0),""),"") | U37: =IF(T37<>"",IF(T37<75,"FAILED","PASSED"),"") | W37: =_xlfn.IFNA(_xlfn.XLOOKUP(AD37,HELPER_SUBJECTS!$I$13:$I$14,HELPER_SUBJECTS!$J$13:$J$14),"") | AC37: =IF(B37="ACADEMIC",HELPER_SUBJECTS!$S$4,IF(B37="TECHPRO",HELPER_SUBJECTS!$T$4,"")) | AD37: =_xlfn.IFNA(_xlfn.XLOOKUP(D37,HELPER_SUBJECTS!D:D,HELPER_SUBJECTS!F:F),0) -> 0 | AE37: =_xlfn.IFNA(IF(D37<>"",_xlfn.XLOOKUP(D37,ANNEX!$F$52:$F$61,ANNEX!$H$52:$H$61),0),0) -> 0 | AF37: =IF(AND(AD37>0,AE37=0),AD37,IF(AND(AE37>0,AD37=0),AE37,0)) -> 0
A38: 9 | T38: =IF(AF38=2,IF(COUNTA(R38:S38)=2,ROUND(AVERAGE(R38:S38),0),""),"") | U38: =IF(T38<>"",IF(T38<75,"FAILED","PASSED"),"") | W38: =_xlfn.IFNA(_xlfn.XLOOKUP(AD38,HELPER_SUBJECTS!$I$13:$I$14,HELPER_SUBJECTS!$J$13:$J$14),"") | AC38: =IF(B38="ACADEMIC",HELPER_SUBJECTS!$S$4,IF(B38="TECHPRO",HELPER_SUBJECTS!$T$4,"")) | AD38: =_xlfn.IFNA(_xlfn.XLOOKUP(D38,HELPER_SUBJECTS!D:D,HELPER_SUBJECTS!F:F),0) -> 0 | AE38: =_xlfn.IFNA(IF(D38<>"",_xlfn.XLOOKUP(D38,ANNEX!$F$52:$F$61,ANNEX!$H$52:$H$61),0),0) -> 0 | AF38: =IF(AND(AD38>0,AE38=0),AD38,IF(AND(AE38>0,AD38=0),AE38,0)) -> 0
A39: 10 | T39: =IF(AF39=2,IF(COUNTA(R39:S39)=2,ROUND(AVERAGE(R39:S39),0),""),"") | U39: =IF(T39<>"",IF(T39<75,"FAILED","PASSED"),"") | W39: =_xlfn.IFNA(_xlfn.XLOOKUP(AD39,HELPER_SUBJECTS!$I$13:$I$14,HELPER_SUBJECTS!$J$13:$J$14),"") | AC39: =IF(B39="ACADEMIC",HELPER_SUBJECTS!$S$4,IF(B39="TECHPRO",HELPER_SUBJECTS!$T$4,"")) | AD39: =_xlfn.IFNA(_xlfn.XLOOKUP(D39,HELPER_SUBJECTS!D:D,HELPER_SUBJECTS!F:F),0) -> 0 | AE39: =_xlfn.IFNA(IF(D39<>"",_xlfn.XLOOKUP(D39,ANNEX!$F$52:$F$61,ANNEX!$H$52:$H$61),0),0) -> 0 | AF39: =IF(AND(AD39>0,AE39=0),AD39,IF(AND(AE39>0,AD39=0),AE39,0)) -> 0
A40: 11 | T40: =IF(AF40=2,IF(COUNTA(R40:S40)=2,ROUND(AVERAGE(R40:S40),0),""),"") | U40: =IF(T40<>"",IF(T40<75,"FAILED","PASSED"),"") | W40: =_xlfn.IFNA(_xlfn.XLOOKUP(AD40,HELPER_SUBJECTS!$I$13:$I$14,HELPER_SUBJECTS!$J$13:$J$14),"") | AC40: =IF(B40="ACADEMIC",HELPER_SUBJECTS!$S$4,IF(B40="TECHPRO",HELPER_SUBJECTS!$T$4,"")) | AD40: =_xlfn.IFNA(_xlfn.XLOOKUP(D40,HELPER_SUBJECTS!D:D,HELPER_SUBJECTS!F:F),0) -> 0 | AE40: =_xlfn.IFNA(IF(D40<>"",_xlfn.XLOOKUP(D40,ANNEX!$F$52:$F$61,ANNEX!$H$52:$H$61),0),0) -> 0 | AF40: =IF(AND(AD40>0,AE40=0),AD40,IF(AND(AE40>0,AD40=0),AE40,0)) -> 0
A41: 12 | T41: =IF(AF41=2,IF(COUNTA(R41:S41)=2,ROUND(AVERAGE(R41:S41),0),""),"") | U41: =IF(T41<>"",IF(T41<75,"FAILED","PASSED"),"") | W41: =_xlfn.IFNA(_xlfn.XLOOKUP(AD41,HELPER_SUBJECTS!$I$13:$I$14,HELPER_SUBJECTS!$J$13:$J$14),"") | AC41: =IF(B41="ACADEMIC",HELPER_SUBJECTS!$S$4,IF(B41="TECHPRO",HELPER_SUBJECTS!$T$4,"")) | AD41: =_xlfn.IFNA(_xlfn.XLOOKUP(D41,HELPER_SUBJECTS!D:D,HELPER_SUBJECTS!F:F),0) -> 0 | AE41: =_xlfn.IFNA(IF(D41<>"",_xlfn.XLOOKUP(D41,ANNEX!$F$52:$F$61,ANNEX!$H$52:$H$61),0),0) -> 0 | AF41: =IF(AND(AD41>0,AE41=0),AD41,IF(AND(AE41>0,AD41=0),AE41,0)) -> 0
A43: Remarks:
A45: Prepared by: | L45: Certified True and Correct: | W45: Date Checked:
A47: Signature of Adviser over Printed Name | L47: Signature of Authorized Person over Printed Name, Designation | W47: MM / DD / YYYY
...

Sheet BACK
Y1: SF10 for SHS
A3: SCHOOL: | M3: SCHOOL ID: | R3: GRADE LEVEL: | S3: 12 | V3: SECTION: | AA3: FIRST SEMESTER / FIRST SEMESTER / FIRST SEMESTER / FIRST SEMESTER / FIRST SEMESTER
A4: TRACK: | R4: SCHOOL YEAR: | V4: SEM: | W4: FIRST
A6: TRACK | D6: SUBJECTS | R6: QUARTERLY GRADE | T6: 1ST SEMESTRAL GRADE | W6: REMARK
T7: GEN. AVE. | U7: ACTION TAKEN
A8: Academic/TechPro | D8: Specific core or elective subject | R8: Q1 | S8: Q2 | W8: Final Grade Computation | AC8: reference / subject list | AD8: Listed | AE8: New | AF8: Quarters
A9: 1 | T9: =IF(AF9=2,IF(COUNTA(R9:S9)=2,ROUND(AVERAGE(R9:S9),0),""),"") | U9: =IF(T9<>"",IF(T9<75,"FAILED","PASSED"),"") | W9: =_xlfn.IFNA(_xlfn.XLOOKUP(AF9,HELPER_SUBJECTS!$I$13:$I$14,HELPER_SUBJECTS!$J$13:$J$14),"") | AC9: =IF(B9="ACADEMIC",HELPER_SUBJECTS!$U$4,IF(B9="TECHPRO",HELPER_SUBJECTS!$V$4,"")) | AD9: =_xlfn.IFNA(_xlfn.XLOOKUP(D9,HELPER_SUBJECTS!D:D,HELPER_SUBJECTS!F:F),0) -> 0 | AE9: =_xlfn.IFNA(IF(D9<>"",_xlfn.XLOOKUP(D9,ANNEX!$F$52:$F$61,ANNEX!$H$52:$H$61),0),0) -> 0 | AF9: =IF(AND(AD9>0,AE9=0),AD9,IF(AND(AE9>0,AD9=0),AE9,0)) -> 0
A10: 2 | T10: =IF(AF10=2,IF(COUNTA(R10:S10)=2,ROUND(AVERAGE(R10:S10),0),""),"") | U10: =IF(T10<>"",IF(T10<75,"FAILED","PASSED"),"") | W10: =_xlfn.IFNA(_xlfn.XLOOKUP(AF10,HELPER_SUBJECTS!$I$13:$I$14,HELPER_SUBJECTS!$J$13:$J$14),"") | AC10: =IF(B10="ACADEMIC",HELPER_SUBJECTS!$U$4,IF(B10="TECHPRO",HELPER_SUBJECTS!$V$4,"")) | AD10: =_xlfn.IFNA(_xlfn.XLOOKUP(D10,HELPER_SUBJECTS!D:D,HELPER_SUBJECTS!F:F),0) -> 0 | AE10: =_xlfn.IFNA(IF(D10<>"",_xlfn.XLOOKUP(D10,ANNEX!$F$52:$F$61,ANNEX!$H$52:$H$61),0),0) -> 0 | AF10: =IF(AND(AD10>0,AE10=0),AD10,IF(AND(AE10>0,AD10=0),AE10,0)) -> 0
A11: 3 | T11: =IF(AF11=2,IF(COUNTA(R11:S11)=2,ROUND(AVERAGE(R11:S11),0),""),"") | U11: =IF(T11<>"",IF(T11<75,"FAILED","PASSED"),"") | W11: =_xlfn.IFNA(_xlfn.XLOOKUP(AF11,HELPER_SUBJECTS!$I$13:$I$14,HELPER_SUBJECTS!$J$13:$J$14),"") | AC11: =IF(B11="ACADEMIC",HELPER_SUBJECTS!$U$4,IF(B11="TECHPRO",HELPER_SUBJECTS!$V$4,"")) | AD11: =_xlfn.IFNA(_xlfn.XLOOKUP(D11,HELPER_SUBJECTS!D:D,HELPER_SUBJECTS!F:F),0) -> 0 | AE11: =_xlfn.IFNA(IF(D11<>"",_xlfn.XLOOKUP(D11,ANNEX!$F$52:$F$61,ANNEX!$H$52:$H$61),0),0) -> 0 | AF11: =IF(AND(AD11>0,AE11=0),AD11,IF(AND(AE11>0,AD11=0),AE11,0)) -> 0
A12: 4 | T12: =IF(AF12=2,IF(COUNTA(R12:S12)=2,ROUND(AVERAGE(R12:S12),0),""),"") | U12: =IF(T12<>"",IF(T12<75,"FAILED","PASSED"),"") | W12: =_xlfn.IFNA(_xlfn.XLOOKUP(AF12,HELPER_SUBJECTS!$I$13:$I$14,HELPER_SUBJECTS!$J$13:$J$14),"") | AC12: =IF(B12="ACADEMIC",HELPER_SUBJECTS!$U$4,IF(B12="TECHPRO",HELPER_SUBJECTS!$V$4,"")) | AD12: =_xlfn.IFNA(_xlfn.XLOOKUP(D12,HELPER_SUBJECTS!D:D,HELPER_SUBJECTS!F:F),0) -> 0 | AE12: =_xlfn.IFNA(IF(D12<>"",_xlfn.XLOOKUP(D12,ANNEX!$F$52:$F$61,ANNEX!$H$52:$H$61),0),0) -> 0 | AF12: =IF(AND(AD12>0,AE12=0),AD12,IF(AND(AE12>0,AD12=0),AE12,0)) -> 0
A13: 5 | T13: =IF(AF13=2,IF(COUNTA(R13:S13)=2,ROUND(AVERAGE(R13:S13),0),""),"") | U13: =IF(T13<>"",IF(T13<75,"FAILED","PASSED"),"") | W13: =_xlfn.IFNA(_xlfn.XLOOKUP(AF13,HELPER_SUBJECTS!$I$13:$I$14,HELPER_SUBJECTS!$J$13:$J$14),"") | AC13: =IF(B13="ACADEMIC",HELPER_SUBJECTS!$U$4,IF(B13="TECHPRO",HELPER_SUBJECTS!$V$4,"")) | AD13: =_xlfn.IFNA(_xlfn.XLOOKUP(D13,HELPER_SUBJECTS!D:D,HELPER_SUBJECTS!F:F),0) -> 0 | AE13: =_xlfn.IFNA(IF(D13<>"",_xlfn.XLOOKUP(D13,ANNEX!$F$52:$F$61,ANNEX!$H$52:$H$61),0),0) -> 0 | AF13: =IF(AND(AD13>0,AE13=0),AD13,IF(AND(AE13>0,AD13=0),AE13,0)) -> 0
A14: 6 | T14: =IF(AF14=2,IF(COUNTA(R14:S14)=2,ROUND(AVERAGE(R14:S14),0),""),"") | U14: =IF(T14<>"",IF(T14<75,"FAILED","PASSED"),"") | W14: =_xlfn.IFNA(_xlfn.XLOOKUP(AF14,HELPER_SUBJECTS!$I$13:$I$14,HELPER_SUBJECTS!$J$13:$J$14),"") | AC14: =IF(B14="ACADEMIC",HELPER_SUBJECTS!$U$4,IF(B14="TECHPRO",HELPER_SUBJECTS!$V$4,"")) | AD14: =_xlfn.IFNA(_xlfn.XLOOKUP(D14,HELPER_SUBJECTS!D:D,HELPER_SUBJECTS!F:F),0) -> 0 | AE14: =_xlfn.IFNA(IF(D14<>"",_xlfn.XLOOKUP(D14,ANNEX!$F$52:$F$61,ANNEX!$H$52:$H$61),0),0) -> 0 | AF14: =IF(AND(AD14>0,AE14=0),AD14,IF(AND(AE14>0,AD14=0),AE14,0)) -> 0
A15: 7 | T15: =IF(AF15=2,IF(COUNTA(R15:S15)=2,ROUND(AVERAGE(R15:S15),0),""),"") | U15: =IF(T15<>"",IF(T15<75,"FAILED","PASSED"),"") | W15: =_xlfn.IFNA(_xlfn.XLOOKUP(AF15,HELPER_SUBJECTS!$I$13:$I$14,HELPER_SUBJECTS!$J$13:$J$14),"") | AC15: =IF(B15="ACADEMIC",HELPER_SUBJECTS!$U$4,IF(B15="TECHPRO",HELPER_SUBJECTS!$V$4,"")) | AD15: =_xlfn.IFNA(_xlfn.XLOOKUP(D15,HELPER_SUBJECTS!D:D,HELPER_SUBJECTS!F:F),0) -> 0 | AE15: =_xlfn.IFNA(IF(D15<>"",_xlfn.XLOOKUP(D15,ANNEX!$F$52:$F$61,ANNEX!$H$52:$H$61),0),0) -> 0 | AF15: =IF(AND(AD15>0,AE15=0),AD15,IF(AND(AE15>0,AD15=0),AE15,0)) -> 0
A16: 8 | T16: =IF(AF16=2,IF(COUNTA(R16:S16)=2,ROUND(AVERAGE(R16:S16),0),""),"") | U16: =IF(T16<>"",IF(T16<75,"FAILED","PASSED"),"") | W16: =_xlfn.IFNA(_xlfn.XLOOKUP(AF16,HELPER_SUBJECTS!$I$13:$I$14,HELPER_SUBJECTS!$J$13:$J$14),"") | AC16: =IF(B16="ACADEMIC",HELPER_SUBJECTS!$U$4,IF(B16="TECHPRO",HELPER_SUBJECTS!$V$4,"")) | AD16: =_xlfn.IFNA(_xlfn.XLOOKUP(D16,HELPER_SUBJECTS!D:D,HELPER_SUBJECTS!F:F),0) -> 0 | AE16: =_xlfn.IFNA(IF(D16<>"",_xlfn.XLOOKUP(D16,ANNEX!$F$52:$F$61,ANNEX!$H$52:$H$61),0),0) -> 0 | AF16: =IF(AND(AD16>0,AE16=0),AD16,IF(AND(AE16>0,AD16=0),AE16,0)) -> 0
A17: 9 | T17: =IF(AF17=2,IF(COUNTA(R17:S17)=2,ROUND(AVERAGE(R17:S17),0),""),"") | U17: =IF(T17<>"",IF(T17<75,"FAILED","PASSED"),"") | W17: =_xlfn.IFNA(_xlfn.XLOOKUP(AF17,HELPER_SUBJECTS!$I$13:$I$14,HELPER_SUBJECTS!$J$13:$J$14),"") | AC17: =IF(B17="ACADEMIC",HELPER_SUBJECTS!$U$4,IF(B17="TECHPRO",HELPER_SUBJECTS!$V$4,"")) | AD17: =_xlfn.IFNA(_xlfn.XLOOKUP(D17,HELPER_SUBJECTS!D:D,HELPER_SUBJECTS!F:F),0) -> 0 | AE17: =_xlfn.IFNA(IF(D17<>"",_xlfn.XLOOKUP(D17,ANNEX!$F$52:$F$61,ANNEX!$H$52:$H$61),0),0) -> 0 | AF17: =IF(AND(AD17>0,AE17=0),AD17,IF(AND(AE17>0,AD17=0),AE17,0)) -> 0
A18: 10 | T18: =IF(AF18=2,IF(COUNTA(R18:S18)=2,ROUND(AVERAGE(R18:S18),0),""),"") | U18: =IF(T18<>"",IF(T18<75,"FAILED","PASSED"),"") | W18: =_xlfn.IFNA(_xlfn.XLOOKUP(AF18,HELPER_SUBJECTS!$I$13:$I$14,HELPER_SUBJECTS!$J$13:$J$14),"") | AC18: =IF(B18="ACADEMIC",HELPER_SUBJECTS!$U$4,IF(B18="TECHPRO",HELPER_SUBJECTS!$V$4,"")) | AD18: =_xlfn.IFNA(_xlfn.XLOOKUP(D18,HELPER_SUBJECTS!D:D,HELPER_SUBJECTS!F:F),0) -> 0 | AE18: =_xlfn.IFNA(IF(D18<>"",_xlfn.XLOOKUP(D18,ANNEX!$F$52:$F$61,ANNEX!$H$52:$H$61),0),0) -> 0 | AF18: =IF(AND(AD18>0,AE18=0),AD18,IF(AND(AE18>0,AD18=0),AE18,0)) -> 0
AC19: =IF(B19="ACADEMIC",HELPER_SUBJECTS!$U$4,IF(B19="TECHPRO",HELPER_SUBJECTS!$V$4,""))
A20: Remarks:
A22: Prepared by: | L22: Certified True and Correct: | W22: Date Checked:
A24: Signature of Adviser over Printed Name | L24: Signature of Authorized Person over Printed Name, Designation | W24: MM / DD / YYYY
A26: REMEDIATION CLASS | G26: Conducted from: | K26: to | P26: School: | W26: School ID:
H27: MM / DD / YYYY | L27: MM / DD / YYYY
A28: TRACK | D28: SUBJECTS | R28: Failed Final Gr. | S28: Remedial Mark | T28: Recomputed | U28: ACTION TAKEN | W28: REMARK
A29: Academic/TechPro | D29: Specific core or elective subject | AC29: reference / subject list
A30: 1 | T30: =IF(OR(R30="",S30=""),"",IF(ISERROR(ROUND(AVERAGE(R30,S30),0)),"",ROUND(AVERAGE(R30,S30),0))) | U30: =IF(T30<>"",IF(T30<75,"FAILED","PASSED"),"") | AC30: =IF(B30="ACADEMIC",HELPER_SUBJECTS!$U$4,IF(B30="TECHPRO",HELPER_SUBJECTS!$V$4,"")) | AD30: =_xlfn.XLOOKUP(D30,HELPER_SUBJECTS!D:D,HELPER_SUBJECTS!G:G) -> 0
A31: 2 | T31: =IF(OR(R31="",S31=""),"",IF(ISERROR(ROUND(AVERAGE(R31,S31),0)),"",ROUND(AVERAGE(R31,S31),0))) | U31: =IF(T31<>"",IF(T31<75,"FAILED","PASSED"),"") | AC31: =IF(B31="ACADEMIC",HELPER_SUBJECTS!$U$4,IF(B31="TECHPRO",HELPER_SUBJECTS!$V$4,"")) | AD31: =_xlfn.XLOOKUP(D31,HELPER_SUBJECTS!D:D,HELPER_SUBJECTS!G:G) -> 0
A32: 3 | T32: =IF(OR(R32="",S32=""),"",IF(ISERROR(ROUND(AVERAGE(R32,S32),0)),"",ROUND(AVERAGE(R32,S32),0))) | U32: =IF(T32<>"",IF(T32<75,"FAILED","PASSED"),"") | AC32: =IF(B32="ACADEMIC",HELPER_SUBJECTS!$U$4,IF(B32="TECHPRO",HELPER_SUBJECTS!$V$4,"")) | AD32: =_xlfn.XLOOKUP(D32,HELPER_SUBJECTS!D:D,HELPER_SUBJECTS!G:G) -> 0
A33: 4 | T33: =IF(OR(R33="",S33=""),"",IF(ISERROR(ROUND(AVERAGE(R33,S33),0)),"",ROUND(AVERAGE(R33,S33),0))) | U33: =IF(T33<>"",IF(T33<75,"FAILED","PASSED"),"") | AC33: =IF(B33="ACADEMIC",HELPER_SUBJECTS!$U$4,IF(B33="TECHPRO",HELPER_SUBJECTS!$V$4,"")) | AD33: =_xlfn.XLOOKUP(D33,HELPER_SUBJECTS!D:D,HELPER_SUBJECTS!G:G) -> 0
AC34: =IF(B34="ACADEMIC",HELPER_SUBJECTS!$U$4,IF(B34="TECHPRO",HELPER_SUBJECTS!$V$4,""))
A35: Name of Teacher/Adviser: | S35: Signature:
A38: SCHOOL: | M38: SCHOOL ID: | R38: GRADE LEVEL: | S38: 12 | V38: SECTION: | AA38: SECOND SEMESTER / SECOND SEMESTER / SECOND SEMESTER / SECOND SEMESTER / SECOND SEM
A39: TRACK: | R39: SCHOOL YEAR: | V39: SEM: | W39: SECOND
A41: TRACK | D41: SUBJECTS | R41: QUARTERLY GRADE | T41: 2ND SEMESTRAL GRADE | W41: REMARK
T42: GEN. AVE. | U42: ACTION TAKEN
A43: Academic/TechPro | D43: Specific core or elective subject | R43: Q3 | S43: Q4 | W43: Final Grade Computation | AC43: reference / subject list | AD43: Listed | AE43: New | AF43: Quarters
A44: 1 | T44: =IF(AF44=2,IF(COUNTA(R44:S44)=2,ROUND(AVERAGE(R44:S44),0),""),"") | U44: =IF(T44<>"",IF(T44<75,"FAILED","PASSED"),"") | W44: =_xlfn.IFNA(_xlfn.XLOOKUP(AF44,HELPER_SUBJECTS!$I$13:$I$14,HELPER_SUBJECTS!$J$13:$J$14),"") | AC44: =IF(B44="ACADEMIC",HELPER_SUBJECTS!$U$4,IF(B44="TECHPRO",HELPER_SUBJECTS!$V$4,"")) | AD44: =_xlfn.IFNA(_xlfn.XLOOKUP(D44,HELPER_SUBJECTS!D:D,HELPER_SUBJECTS!F:F),0) -> 0 | AE44: =_xlfn.IFNA(IF(D44<>"",_xlfn.XLOOKUP(D44,ANNEX!$F$52:$F$61,ANNEX!$H$52:$H$61),0),0) -> 0 | AF44: =IF(AND(AD44>0,AE44=0),AD44,IF(AND(AE44>0,AD44=0),AE44,0)) -> 0
A45: 2 | T45: =IF(AF45=2,IF(COUNTA(R45:S45)=2,ROUND(AVERAGE(R45:S45),0),""),"") | U45: =IF(T45<>"",IF(T45<75,"FAILED","PASSED"),"") | W45: =_xlfn.IFNA(_xlfn.XLOOKUP(AF45,HELPER_SUBJECTS!$I$13:$I$14,HELPER_SUBJECTS!$J$13:$J$14),"") | AC45: =IF(B45="ACADEMIC",HELPER_SUBJECTS!$U$4,IF(B45="TECHPRO",HELPER_SUBJECTS!$V$4,"")) | AD45: =_xlfn.IFNA(_xlfn.XLOOKUP(D45,HELPER_SUBJECTS!D:D,HELPER_SUBJECTS!F:F),0) -> 0 | AE45: =_xlfn.IFNA(IF(D45<>"",_xlfn.XLOOKUP(D45,ANNEX!$F$52:$F$61,ANNEX!$H$52:$H$61),0),0) -> 0 | AF45: =IF(AND(AD45>0,AE45=0),AD45,IF(AND(AE45>0,AD45=0),AE45,0)) -> 0
A46: 3 | T46: =IF(AF46=2,IF(COUNTA(R46:S46)=2,ROUND(AVERAGE(R46:S46),0),""),"") | U46: =IF(T46<>"",IF(T46<75,"FAILED","PASSED"),"") | W46: =_xlfn.IFNA(_xlfn.XLOOKUP(AF46,HELPER_SUBJECTS!$I$13:$I$14,HELPER_SUBJECTS!$J$13:$J$14),"") | AC46: =IF(B46="ACADEMIC",HELPER_SUBJECTS!$U$4,IF(B46="TECHPRO",HELPER_SUBJECTS!$V$4,"")) | AD46: =_xlfn.IFNA(_xlfn.XLOOKUP(D46,HELPER_SUBJECTS!D:D,HELPER_SUBJECTS!F:F),0) -> 0 | AE46: =_xlfn.IFNA(IF(D46<>"",_xlfn.XLOOKUP(D46,ANNEX!$F$52:$F$61,ANNEX!$H$52:$H$61),0),0) -> 0 | AF46: =IF(AND(AD46>0,AE46=0),AD46,IF(AND(AE46>0,AD46=0),AE46,0)) -> 0
A47: 4 | T47: =IF(AF47=2,IF(COUNTA(R47:S47)=2,ROUND(AVERAGE(R47:S47),0),""),"") | U47: =IF(T47<>"",IF(T47<75,"FAILED","PASSED"),"") | W47: =_xlfn.IFNA(_xlfn.XLOOKUP(AF47,HELPER_SUBJECTS!$I$13:$I$14,HELPER_SUBJECTS!$J$13:$J$14),"") | AC47: =IF(B47="ACADEMIC",HELPER_SUBJECTS!$U$4,IF(B47="TECHPRO",HELPER_SUBJECTS!$V$4,"")) | AD47: =_xlfn.IFNA(_xlfn.XLOOKUP(D47,HELPER_SUBJECTS!D:D,HELPER_SUBJECTS!F:F),0) -> 0 | AE47: =_xlfn.IFNA(IF(D47<>"",_xlfn.XLOOKUP(D47,ANNEX!$F$52:$F$61,ANNEX!$H$52:$H$61),0),0) -> 0 | AF47: =IF(AND(AD47>0,AE47=0),AD47,IF(AND(AE47>0,AD47=0),AE47,0)) -> 0
A48: 5 | T48: =IF(AF48=2,IF(COUNTA(R48:S48)=2,ROUND(AVERAGE(R48:S48),0),""),"") | U48: =IF(T48<>"",IF(T48<75,"FAILED","PASSED"),"") | W48: =_xlfn.IFNA(_xlfn.XLOOKUP(AF48,HELPER_SUBJECTS!$I$13:$I$14,HELPER_SUBJECTS!$J$13:$J$14),"") | AC48: =IF(B48="ACADEMIC",HELPER_SUBJECTS!$U$4,IF(B48="TECHPRO",HELPER_SUBJECTS!$V$4,"")) | AD48: =_xlfn.IFNA(_xlfn.XLOOKUP(D48,HELPER_SUBJECTS!D:D,HELPER_SUBJECTS!F:F),0) -> 0 | AE48: =_xlfn.IFNA(IF(D48<>"",_xlfn.XLOOKUP(D48,ANNEX!$F$52:$F$61,ANNEX!$H$52:$H$61),0),0) -> 0 | AF48: =IF(AND(AD48>0,AE48=0),AD48,IF(AND(AE48>0,AD48=0),AE48,0)) -> 0
...

Sheet ANNEX
H1: SF10 for SHS
A3: ANNEX: LIST OF SUBJECTS TAKEN
A4: Please check the subjects passed by the student
A6: CORE SUBJECTS | I6: REMARK | J6: SOURCE
A7: 1 | B7: =IF(I7="PASSED","P"," ") | D7: Effective Communication & Mabisang Komunikasyon | I7: =_xlfn.XLOOKUP(D7,FRONT!$D$104:$D$122,FRONT!$X$104:$X$122)
A8: 1A | B8: =IF(I8="PASSED","P"," ") | D8: Effective Communication | I8: =_xlfn.XLOOKUP(D8,FRONT!$D$104:$D$122,FRONT!$X$104:$X$122)
A9: 1B | B9: =IF(I9="PASSED","P"," ") | D9: Mabisang Komunikasyon | I9: =_xlfn.XLOOKUP(D9,FRONT!$D$104:$D$122,FRONT!$X$104:$X$122)
A10: 2 | B10: =IF(I10="PASSED","P"," ") | D10: General Mathematics | I10: =_xlfn.XLOOKUP(D10,FRONT!$D$104:$D$122,FRONT!$X$104:$X$122)
A11: 3 | B11: =IF(I11="PASSED","P"," ") | D11: General Science | I11: =_xlfn.XLOOKUP(D11,FRONT!$D$104:$D$122,FRONT!$X$104:$X$122)
A12: 4 | B12: =IF(I12="PASSED","P"," ") | D12: Life and Career Skills | I12: =_xlfn.XLOOKUP(D12,FRONT!$D$104:$D$122,FRONT!$X$104:$X$122)
A13: 5 | B13: =IF(I13="PASSED","P"," ") | D13: Pag-aaral ng Kasaysayan at Lipunang Pilipino | I13: =_xlfn.XLOOKUP(D13,FRONT!$D$104:$D$122,FRONT!$X$104:$X$122)
A16: ACADEMIC ELECTIVES
A17: 1 | B17: =IF(I17="PASSED","P"," ") | I17: =IFERROR(_xlfn.XLOOKUP(D17,FRONT!$D$104:$D$122,FRONT!$X$104:$X$122),FALSE)
A18: 2 | B18: =IF(I18="PASSED","P"," ") | I18: =IFERROR(_xlfn.XLOOKUP(D18,FRONT!$D$104:$D$122,FRONT!$X$104:$X$122),FALSE)
A19: 3 | B19: =IF(I19="PASSED","P"," ") | I19: =IFERROR(_xlfn.XLOOKUP(D19,FRONT!$D$104:$D$122,FRONT!$X$104:$X$122),FALSE)
A20: 4 | B20: =IF(I20="PASSED","P"," ") | I20: =IFERROR(_xlfn.XLOOKUP(D20,FRONT!$D$104:$D$122,FRONT!$X$104:$X$122),FALSE)
A21: 5 | B21: =IF(I21="PASSED","P"," ") | I21: =IFERROR(_xlfn.XLOOKUP(D21,FRONT!$D$104:$D$122,FRONT!$X$104:$X$122),FALSE)
A22: 6 | B22: =IF(I22="PASSED","P"," ") | I22: =IFERROR(_xlfn.XLOOKUP(D22,FRONT!$D$104:$D$122,FRONT!$X$104:$X$122),FALSE)
A23: 7 | B23: =IF(I23="PASSED","P"," ") | I23: =IFERROR(_xlfn.XLOOKUP(D23,FRONT!$D$104:$D$122,FRONT!$X$104:$X$122),FALSE)
A24: 8 | B24: =IF(I24="PASSED","P"," ") | I24: =IFERROR(_xlfn.XLOOKUP(D24,FRONT!$D$104:$D$122,FRONT!$X$104:$X$122),FALSE)
A25: 9 | B25: =IF(I25="PASSED","P"," ") | I25: =IFERROR(_xlfn.XLOOKUP(D25,FRONT!$D$104:$D$122,FRONT!$X$104:$X$122),FALSE)
A26: 10 | B26: =IF(I26="PASSED","P"," ") | I26: =IFERROR(_xlfn.XLOOKUP(D26,FRONT!$D$104:$D$122,FRONT!$X$104:$X$122),FALSE)
A27: 11 | B27: =IF(I27="PASSED","P"," ") | I27: =IFERROR(_xlfn.XLOOKUP(D27,FRONT!$D$104:$D$122,FRONT!$X$104:$X$122),FALSE)
A28: 12 | B28: =IF(I28="PASSED","P"," ") | I28: =IFERROR(_xlfn.XLOOKUP(D28,FRONT!$D$104:$D$122,FRONT!$X$104:$X$122),FALSE)
... A31: 15 | B31: =IF(I31="PASSED","P"," ") | I31: =IFERROR(_xlfn.XLOOKUP(D31,FRONT!$D$104:$D$122,FRONT!$X$104:$X$122),FALSE)
A33: TECHPRO ELECTIVES
A34: 1 | B34: =IF(I34="PASSED","P"," ") | I34: =IFERROR(_xlfn.XLOOKUP(D34,FRONT!$D$104:$D$122,FRONT!$X$104:$X$122),FALSE)
A35: 2 | B35: =IF(I35="PASSED","P"," ") | I35: =IFERROR(_xlfn.XLOOKUP(D35,FRONT!$D$104:$D$122,FRONT!$X$104:$X$122),FALSE)
A36: 3 | B36: =IF(I36="PASSED","P"," ") | I36: =IFERROR(_xlfn.XLOOKUP(D36,FRONT!$D$104:$D$122,FRONT!$X$104:$X$122),FALSE)
A37: 4 | B37: =IF(I37="PASSED","P"," ") | I37: =IFERROR(_xlfn.XLOOKUP(D37,FRONT!$D$104:$D$122,FRONT!$X$104:$X$122),FALSE)
A38: 5 | B38: =IF(I38="PASSED","P"," ") | I38: =IFERROR(_xlfn.XLOOKUP(D38,FRONT!$D$104:$D$122,FRONT!$X$104:$X$122),FALSE)
A39: 6 | B39: =IF(I39="PASSED","P"," ") | I39: =IFERROR(_xlfn.XLOOKUP(D39,FRONT!$D$104:$D$122,FRONT!$X$104:$X$122),FALSE)
A40: 7 | B40: =IF(I40="PASSED","P"," ") | I40: =IFERROR(_xlfn.XLOOKUP(D40,FRONT!$D$104:$D$122,FRONT!$X$104:$X$122),FALSE)
A41: 8 | B41: =IF(I41="PASSED","P"," ") | I41: =IFERROR(_xlfn.XLOOKUP(D41,FRONT!$D$104:$D$122,FRONT!$X$104:$X$122),FALSE)
A42: 9 | B42: =IF(I42="PASSED","P"," ") | I42: =IFERROR(_xlfn.XLOOKUP(D42,FRONT!$D$104:$D$122,FRONT!$X$104:$X$122),FALSE)
A43: 10 | B43: =IF(I43="PASSED","P"," ") | I43: =IFERROR(_xlfn.XLOOKUP(D43,FRONT!$D$104:$D$122,FRONT!$X$104:$X$122),FALSE)
A44: 11 | B44: =IF(I44="PASSED","P"," ") | I44: =IFERROR(_xlfn.XLOOKUP(D44,FRONT!$D$104:$D$122,FRONT!$X$104:$X$122),FALSE)
A45: 12 | B45: =IF(I45="PASSED","P"," ") | I45: =IFERROR(_xlfn.XLOOKUP(D45,FRONT!$D$104:$D$122,FRONT!$X$104:$X$122),FALSE)
... A48: 15 | B48: =IF(I48="PASSED","P"," ") | I48: =IFERROR(_xlfn.XLOOKUP(D48,FRONT!$D$104:$D$122,FRONT!$X$104:$X$122),FALSE)
A50: OTHER SUBJECTS | H50: Please list the subjects and indicate the corresponding number of quarters in which they are offered (2 or 4).
...

Sheet HELPER_SUBJECTS
X1: SUBJECTS | Y1: 11 | Z1: 12 | AA1: REMARKS | AB1: Elective | AC1: Cluster | AD1: Subject | AE1: Q1 | AF1: Q2 | AG1: Q3 | AH1: Q4 | AI1: Remediation
A2: > | B2: HELPER SHEET | S2: Final List of Subjects for Dropdown | X2: Core Subject (All Tracks) | Y2: 4 | AB2: Core Subject (All Tracks) | AC2: CORE | AD2: Effective Communication
A3: >> | B3: SSHSSF102026 | M3: CORE | N3: ACADEMIC | P3: TECHPRO | S3: ACADEMIC 11 | T3: TECHPRO 11 | U3: ACADEMIC 12 | V3: TECHPRO 12 | X3: Academic Elective (All Other Electives) | Y3: 2 | Z3: 2 | AB3: Core Subject (All Tracks) | AC3: CORE | AD3: Mabisang Komunikasyon
M4: 'HELPER_SUBJECTS'!m7:m76 | N4: 'HELPER_SUBJECTS'!n7:n76 | P4: 'HELPER_SUBJECTS'!p7:p76 | S4: 'HELPER_SUBJECTS'!S7:S76 | T4: 'HELPER_SUBJECTS'!T7:T76 | U4: 'HELPER_SUBJECTS'!U7:U76 | V4: 'HELPER_SUBJECTS'!V7:V76 | X4: Academic Elective (Field Experience / Exposure, and Sports and Arts) | Y4: 2 | Z4: 2 | AB4: Core Subject (All Tracks) | AC4: CORE | AD4: General Mathematics
B5: Track | C5: Cluster | D5: Subject | E5: HELPER | F5: 11 | G5: 12 | H5: Grade Lvl | K5: TRACK/CLUSTER | M5: SUBJECTS | N5: SUBJECTS | O5: G LVL | P5: SUBJECTS | Q5: G LVL | S5: SUBJECTS | T5: SUBJECTS | U5: SUBJECTS | V5: SUBJECTS | X5: TechPro Elective (All Other Electives) | Y5: 4 | Z5: 2 | AB5: Core Subject (All Tracks) | AC5: CORE | AD5: General Science
B6: CORE | C6: CORE | D6: Effective Communication | E6: =B6&" - "&C6 -> CORE - CORE | F6: 4 | H6: =IF(AND(F6<>"",G6<>""),"11/12",IF(F6<>"",11,12)) -> 11 | I6: {=_xlfn.UNIQUE(B6:B137)} -> CORE | J6: 'HELPER_SUBJECTS'!L6:L11 | X6: TechPro Elective (Work Immersion) | Y6: 4 | Z6: 2 | AB6: Core Subject (All Tracks) | AC6: CORE | AD6: Life and Career Skills
B7: CORE | C7: CORE | D7: Mabisang Komunikasyon | E7: =B7&" - "&C7 -> CORE - CORE | F7: 4 | H7: =IF(AND(F7<>"",G7<>""),"11/12",IF(F7<>"",11,12)) -> 11 | I7: ACADEMIC | J7: 'HELPER_SUBJECTS'!M6:M76 | K7: ACADEMIC - ARTS, SOCIAL SCIENCE AND HUMANITIES CLUSTER | L7: {=_xlfn.SEQUENCE(70)} -> 1 | M7: Effective Communication | N7: {=_xlfn._xlws.FILTER( _xlfn.VSTACK( ANNEX!D17:D31, IFERROR(_xlfn._xlws.FILTER(ANNEX!F52:F61, ANNEX!D52:D61="ACADEMIC"), "") ), _xlfn.VSTACK( ANNEX!D17:D31, IFERROR(_xlfn._xlws.FILTER(ANNEX!F52:F61, ANNEX!D52:D61="ACADEMIC"), "") )<>"" )} -> #VALUE! | O7: =_xlfn.IFNA(IF(N7<>"",_xlfn.XLOOKUP(N7,$D$6:$D$138,$H$6:$H$138),""),"11/12") -> #VALUE! | P7: {=_xlfn._xlws.FILTER( _xlfn.VSTACK( ANNEX!D34:D48, IFERROR(_xlfn._xlws.FILTER(ANNEX!F52:F61, ANNEX!D52:D61="TECHPRO"), "") ), _xlfn.VSTACK( ANNEX!D34:D48, IFERROR(_xlfn._xlws.FILTER(ANNEX!F52:F61, ANNEX!D52:D61="TECHPRO"), "") )<>"" )} -> #VALUE! | Q7: =_xlfn.IFNA(IF(P7<>"",_xlfn.XLOOKUP(P7,$D$6:$D$138,$H$6:$H$138),""),"11/12") -> #VALUE! | R7: {=_xlfn.SEQUENCE(70)} -> 1 | S7: {=IFERROR(_xlfn._xlws.FILTER($N$7:$N$76,ISNUMBER(SEARCH("11",$O$7:$O$76))),"List ACADEMIC ELECTIVES in the ANNEX sheet.")} -> List ACADEMIC ELECTIVES in the ANNEX sheet. | T7: {=IFERROR(_xlfn._xlws.FILTER($P$7:$P$76, ISNUMBER(SEARCH("11", $Q$7:$Q$76))),"List TECHPRO electives in the ANNEX sheet.")} -> List TECHPRO electives in the ANNEX sheet. | U7: {=IFERROR(_xlfn._xlws.FILTER($N$7:$N$76,ISNUMBER(SEARCH("12",$O$7:$O$76))),"List ACADEMIC ELECTIVES in the ANNEX sheet.")} -> List ACADEMIC ELECTIVES in the ANNEX sheet. | V7: {=IFERROR(_xlfn._xlws.FILTER($P$7:$P$76, ISNUMBER(SEARCH("12", $Q$7:$Q$76))),"List TECHPRO ELECTIVES in the ANNEX sheet.")} -> List TECHPRO ELECTIVES in the ANNEX sheet. | AB7: Core Subject (All Tracks) | AC7: CORE | AD7: Pag-aaral ng Kasaysayan at Lipunang Pilipino
B8: CORE | C8: CORE | D8: General Mathematics | E8: =B8&" - "&C8 -> CORE - CORE | F8: 4 | H8: =IF(AND(F8<>"",G8<>""),"11/12",IF(F8<>"",11,12)) -> 11 | I8: TECHPRO | J8: 'HELPER_SUBJECTS'!N6:N76 | K8: ACADEMIC - BUSINESS AND ENTREPRENEURSHIP | L8: 2 | M8: Mabisang Komunikasyon | O8: =_xlfn.IFNA(IF(N8<>"",_xlfn.XLOOKUP(N8,$D$6:$D$138,$H$6:$H$138),""),"11/12") | Q8: =_xlfn.IFNA(IF(P8<>"",_xlfn.XLOOKUP(P8,$D$6:$D$138,$H$6:$H$138),""),"11/12") | R8: 2 | AB8: Academic Elective (All Other Electives) | AC8: ARTS, SOCIAL SCIENCE AND HUMANITIES CLUSTER | AD8: Arts 1 (Creative Industries - Visual Art, Literary Art, Media Art, Applied Art, and Traditional Art)
B9: CORE | C9: CORE | D9: General Science | E9: =B9&" - "&C9 -> CORE - CORE | F9: 4 | H9: =IF(AND(F9<>"",G9<>""),"11/12",IF(F9<>"",11,12)) -> 11 | K9: ACADEMIC - SCIENCE, TECHNOLOGY, ENGINEERING AND MATHEMATICS | L9: 3 | M9: General Mathematics | O9: =_xlfn.IFNA(IF(N9<>"",_xlfn.XLOOKUP(N9,$D$6:$D$138,$H$6:$H$138),""),"11/12") | Q9: =_xlfn.IFNA(IF(P9<>"",_xlfn.XLOOKUP(P9,$D$6:$D$138,$H$6:$H$138),""),"11/12") | R9: 3 | AB9: Academic Elective (All Other Electives) | AC9: ARTS, SOCIAL SCIENCE AND HUMANITIES CLUSTER | AD9: Arts 2 (Creative Industries - Music, Dance, and Theater)
B10: CORE | C10: CORE | D10: Life and Career Skills | E10: =B10&" - "&C10 -> CORE - CORE | F10: 4 | H10: =IF(AND(F10<>"",G10<>""),"11/12",IF(F10<>"",11,12)) -> 11 | K10: ACADEMIC - SPORTS, HEALTH AND WELLNESS | L10: 4 | M10: General Science | O10: =_xlfn.IFNA(IF(N10<>"",_xlfn.XLOOKUP(N10,$D$6:$D$138,$H$6:$H$138),""),"11/12") | Q10: =_xlfn.IFNA(IF(P10<>"",_xlfn.XLOOKUP(P10,$D$6:$D$138,$H$6:$H$138),""),"11/12") | R10: 4 | AB10: Academic Elective (All Other Electives) | AC10: ARTS, SOCIAL SCIENCE AND HUMANITIES CLUSTER | AD10: Filipino Identity Through the Arts
B11: CORE | C11: CORE | D11: Pag-aaral ng Kasaysayan at Lipunang Pilipino | E11: =B11&" - "&C11 -> CORE - CORE | F11: 4 | H11: =IF(AND(F11<>"",G11<>""),"11/12",IF(F11<>"",11,12)) -> 11 | I11: GRADING SYSTEM | K11: ACADEMIC - FIELD EXPOSURE, ARTS AND SPORTS | L11: 5 | M11: Life and Career Skills | O11: =_xlfn.IFNA(IF(N11<>"",_xlfn.XLOOKUP(N11,$D$6:$D$138,$H$6:$H$138),""),"11/12") | Q11: =_xlfn.IFNA(IF(P11<>"",_xlfn.XLOOKUP(P11,$D$6:$D$138,$H$6:$H$138),""),"11/12") | R11: 5 | AB11: Academic Elective (All Other Electives) | AC11: ARTS, SOCIAL SCIENCE AND HUMANITIES CLUSTER | AD11: Leadership and Mangement in the Arts
B12: ACADEMIC | C12: ARTS, SOCIAL SCIENCE AND HUMANITIES CLUSTER | D12: Arts 1 (Creative Industries - Visual Art, Literary Art, Media Art, Applied Art, and Traditional Art) | E12: =B12&" - "&C12 -> ACADEMIC - ARTS, SOCIAL SCIENCE AND HUMANITIES CLUSTER | F12: 2 | H12: =IF(AND(F12<>"",G12<>""),"11/12",IF(F12<>"",11,12)) -> 11 | I12: Code | J12: Computation | K12: TECHPRO - AESTHETIC, WELLNESS AND HUMAN CARE CLUSTER | L12: 6 | M12: Pag-aaral ng Kasaysayan at Lipunang Pilipino | O12: =_xlfn.IFNA(IF(N12<>"",_xlfn.XLOOKUP(N12,$D$6:$D$138,$H$6:$H$138),""),"11/12") | Q12: =_xlfn.IFNA(IF(P12<>"",_xlfn.XLOOKUP(P12,$D$6:$D$138,$H$6:$H$138),""),"11/12") | R12: 6 | AB12: Academic Elective (All Other Electives) | AC12: ARTS, SOCIAL SCIENCE AND HUMANITIES CLUSTER | AD12: Citizenship and Civic Engagement
B13: ACADEMIC | C13: ARTS, SOCIAL SCIENCE AND HUMANITIES CLUSTER | D13: Arts 2 (Creative Industries - Music, Dance, and Theater) | E13: =B13&" - "&C13 -> ACADEMIC - ARTS, SOCIAL SCIENCE AND HUMANITIES CLUSTER | F13: 2 | H13: =IF(AND(F13<>"",G13<>""),"11/12",IF(F13<>"",11,12)) -> 11 | I13: 2 | J13: Ave. of 2 Qs; Sem. Grade | K13: TECHPRO - AGRI-FISHERY BUSINESS AND FOOD INNOVATION | L13: 7 | O13: =_xlfn.IFNA(IF(N13<>"",_xlfn.XLOOKUP(N13,$D$6:$D$138,$H$6:$H$138),""),"11/12") | Q13: =_xlfn.IFNA(IF(P13<>"",_xlfn.XLOOKUP(P13,$D$6:$D$138,$H$6:$H$138),""),"11/12") | R13: 7 | AB13: Academic Elective (All Other Electives) | AC13: ARTS, SOCIAL SCIENCE AND HUMANITIES CLUSTER | AD13: Contemporary Literature 1
B14: ACADEMIC | C14: ARTS, SOCIAL SCIENCE AND HUMANITIES CLUSTER | D14: Filipino Identity Through the Arts | E14: =B14&" - "&C14 -> ACADEMIC - ARTS, SOCIAL SCIENCE AND HUMANITIES CLUSTER | F14: 2 | H14: =IF(AND(F14<>"",G14<>""),"11/12",IF(F14<>"",11,12)) -> 11 | I14: 4 | J14: Ave. of 4 Qs; No Sem.Grade | K14: TECHPRO - ARTISANRY AND CREATIVE ENTERPRISE | L14: 8 | O14: =_xlfn.IFNA(IF(N14<>"",_xlfn.XLOOKUP(N14,$D$6:$D$138,$H$6:$H$138),""),"11/12") | Q14: =_xlfn.IFNA(IF(P14<>"",_xlfn.XLOOKUP(P14,$D$6:$D$138,$H$6:$H$138),""),"11/12") | R14: 8 | AB14: Academic Elective (All Other Electives) | AC14: ARTS, SOCIAL SCIENCE AND HUMANITIES CLUSTER | AD14: Contemporary Literature 2
B15: ACADEMIC | C15: ARTS, SOCIAL SCIENCE AND HUMANITIES CLUSTER | D15: Leadership and Mangement in the Arts | E15: =B15&" - "&C15 -> ACADEMIC - ARTS, SOCIAL SCIENCE AND HUMANITIES CLUSTER | F15: 2 | H15: =IF(AND(F15<>"",G15<>""),"11/12",IF(F15<>"",11,12)) -> 11 | K15: TECHPRO - AUTOMOTIVE AND SMALL ENGINE TECHNOLOGIES | L15: 9 | O15: =_xlfn.IFNA(IF(N15<>"",_xlfn.XLOOKUP(N15,$D$6:$D$138,$H$6:$H$138),""),"11/12") | Q15: =_xlfn.IFNA(IF(P15<>"",_xlfn.XLOOKUP(P15,$D$6:$D$138,$H$6:$H$138),""),"11/12") | R15: 9 | AB15: Academic Elective (All Other Electives) | AC15: ARTS, SOCIAL SCIENCE AND HUMANITIES CLUSTER | AD15: Creative Composition 1
B16: ACADEMIC | C16: ARTS, SOCIAL SCIENCE AND HUMANITIES CLUSTER | D16: Citizenship and Civic Engagement | E16: =B16&" - "&C16 -> ACADEMIC - ARTS, SOCIAL SCIENCE AND HUMANITIES CLUSTER | F16: 2 | G16: 2 | H16: =IF(AND(F16<>"",G16<>""),"11/12",IF(F16<>"",11,12)) -> 11/12 | K16: TECHPRO - CONSTRUCTION AND BUILDING TECHNOLOGIES | L16: 10 | O16: =_xlfn.IFNA(IF(N16<>"",_xlfn.XLOOKUP(N16,$D$6:$D$138,$H$6:$H$138),""),"11/12") | Q16: =_xlfn.IFNA(IF(P16<>"",_xlfn.XLOOKUP(P16,$D$6:$D$138,$H$6:$H$138),""),"11/12") | R16: 10 | AB16: Academic Elective (All Other Electives) | AC16: ARTS, SOCIAL SCIENCE AND HUMANITIES CLUSTER | AD16: Creative Composition 2
B17: ACADEMIC | C17: ARTS, SOCIAL SCIENCE AND HUMANITIES CLUSTER | D17: Contemporary Literature 1 | E17: =B17&" - "&C17 -> ACADEMIC - ARTS, SOCIAL SCIENCE AND HUMANITIES CLUSTER | F17: 2 | G17: 2 | H17: =IF(AND(F17<>"",G17<>""),"11/12",IF(F17<>"",11,12)) -> 11/12 | K17: TECHPRO - CREATIVE ARTS AND DESIGN TECHNOLOGIES | L17: 11 | O17: =_xlfn.IFNA(IF(N17<>"",_xlfn.XLOOKUP(N17,$D$6:$D$138,$H$6:$H$138),""),"11/12") | Q17: =_xlfn.IFNA(IF(P17<>"",_xlfn.XLOOKUP(P17,$D$6:$D$138,$H$6:$H$138),""),"11/12") | R17: 11 | AB17: Academic Elective (All Other Electives) | AC17: ARTS, SOCIAL SCIENCE AND HUMANITIES CLUSTER | AD17: Filipino 1 (Wika at Komunikasyon sa Akademikong Filipino)
B18: ACADEMIC | C18: ARTS, SOCIAL SCIENCE AND HUMANITIES CLUSTER | D18: Contemporary Literature 2 | E18: =B18&" - "&C18 -> ACADEMIC - ARTS, SOCIAL SCIENCE AND HUMANITIES CLUSTER | F18: 2 | G18: 2 | H18: =IF(AND(F18<>"",G18<>""),"11/12",IF(F18<>"",11,12)) -> 11/12 | K18: TECHPRO - HOSPITALITY AND TOURISM | L18: 12 | O18: =_xlfn.IFNA(IF(N18<>"",_xlfn.XLOOKUP(N18,$D$6:$D$138,$H$6:$H$138),""),"11/12") | Q18: =_xlfn.IFNA(IF(P18<>"",_xlfn.XLOOKUP(P18,$D$6:$D$138,$H$6:$H$138),""),"11/12") | R18: 12 | AB18: Academic Elective (All Other Electives) | AC18: ARTS, SOCIAL SCIENCE AND HUMANITIES CLUSTER | AD18: Filipino 2 (Filipino para sa Larang Teknikal-Propesyonal)
B19: ACADEMIC | C19: ARTS, SOCIAL SCIENCE AND HUMANITIES CLUSTER | D19: Creative Composition 1 | E19: =B19&" - "&C19 -> ACADEMIC - ARTS, SOCIAL SCIENCE AND HUMANITIES CLUSTER | F19: 2 | H19: =IF(AND(F19<>"",G19<>""),"11/12",IF(F19<>"",11,12)) -> 11 | K19: TECHPRO - INDUSTRIAL TECHNOLOGIES | L19: 13 | O19: =_xlfn.IFNA(IF(N19<>"",_xlfn.XLOOKUP(N19,$D$6:$D$138,$H$6:$H$138),""),"11/12") | Q19: =_xlfn.IFNA(IF(P19<>"",_xlfn.XLOOKUP(P19,$D$6:$D$138,$H$6:$H$138),""),"11/12") | R19: 13 | AB19: Academic Elective (All Other Electives) | AC19: ARTS, SOCIAL SCIENCE AND HUMANITIES CLUSTER | AD19: Filipino 2 (Filipino sa Isports)
B20: ACADEMIC | C20: ARTS, SOCIAL SCIENCE AND HUMANITIES CLUSTER | D20: Creative Composition 2 | E20: =B20&" - "&C20 -> ACADEMIC - ARTS, SOCIAL SCIENCE AND HUMANITIES CLUSTER | F20: 2 | H20: =IF(AND(F20<>"",G20<>""),"11/12",IF(F20<>"",11,12)) -> 11 | K20: TECHPRO - ICT SUPPORT AND COMPUTER PROGRAMMING TECHNOLOGIES | L20: 14 | O20: =_xlfn.IFNA(IF(N20<>"",_xlfn.XLOOKUP(N20,$D$6:$D$138,$H$6:$H$138),""),"11/12") | Q20: =_xlfn.IFNA(IF(P20<>"",_xlfn.XLOOKUP(P20,$D$6:$D$138,$H$6:$H$138),""),"11/12") | R20: 14 | AB20: Academic Elective (All Other Electives) | AC20: ARTS, SOCIAL SCIENCE AND HUMANITIES CLUSTER | AD20: Filipino 2 (Filipino sa Sining at Disenyo)
B21: ACADEMIC | C21: ARTS, SOCIAL SCIENCE AND HUMANITIES CLUSTER | D21: Filipino 1 (Wika at Komunikasyon sa Akademikong Filipino) | E21: =B21&" - "&C21 -> ACADEMIC - ARTS, SOCIAL SCIENCE AND HUMANITIES CLUSTER | F21: 2 | G21: 2 | H21: =IF(AND(F21<>"",G21<>""),"11/12",IF(F21<>"",11,12)) -> 11/12 | K21: TECHPRO - MARITIME TRANSPORT | L21: 15 | O21: =_xlfn.IFNA(IF(N21<>"",_xlfn.XLOOKUP(N21,$D$6:$D$138,$H$6:$H$138),""),"11/12") | Q21: =_xlfn.IFNA(IF(P21<>"",_xlfn.XLOOKUP(P21,$D$6:$D$138,$H$6:$H$138),""),"11/12") | R21: 15 | AB21: Academic Elective (All Other Electives) | AC21: ARTS, SOCIAL SCIENCE AND HUMANITIES CLUSTER | AD21: Introduction to Philosophy
B22: ACADEMIC | C22: ARTS, SOCIAL SCIENCE AND HUMANITIES CLUSTER | D22: Filipino 2 (Filipino para sa Larang Teknikal-Propesyonal) | E22: =B22&" - "&C22 -> ACADEMIC - ARTS, SOCIAL SCIENCE AND HUMANITIES CLUSTER | F22: 2 | G22: 2 | H22: =IF(AND(F22<>"",G22<>""),"11/12",IF(F22<>"",11,12)) -> 11/12 | L22: 16 | O22: =_xlfn.IFNA(IF(N22<>"",_xlfn.XLOOKUP(N22,$D$6:$D$138,$H$6:$H$138),""),"11/12") | Q22: =_xlfn.IFNA(IF(P22<>"",_xlfn.XLOOKUP(P22,$D$6:$D$138,$H$6:$H$138),""),"11/12") | R22: 16 | AB22: Academic Elective (All Other Electives) | AC22: ARTS, SOCIAL SCIENCE AND HUMANITIES CLUSTER | AD22: Malikhaing Pagsulat
B23: ACADEMIC | C23: ARTS, SOCIAL SCIENCE AND HUMANITIES CLUSTER | D23: Filipino 2 (Filipino sa Isports) | E23: =B23&" - "&C23 -> ACADEMIC - ARTS, SOCIAL SCIENCE AND HUMANITIES CLUSTER | F23: 2 | G23: 2 | H23: =IF(AND(F23<>"",G23<>""),"11/12",IF(F23<>"",11,12)) -> 11/12 | L23: 17 | O23: =_xlfn.IFNA(IF(N23<>"",_xlfn.XLOOKUP(N23,$D$6:$D$138,$H$6:$H$138),""),"11/12") | Q23: =_xlfn.IFNA(IF(P23<>"",_xlfn.XLOOKUP(P23,$D$6:$D$138,$H$6:$H$138),""),"11/12") | R23: 17 | AB23: Academic Elective (All Other Electives) | AC23: ARTS, SOCIAL SCIENCE AND HUMANITIES CLUSTER | AD23: Philippine Governance (Philippine Politics and Governance)
B24: ACADEMIC | C24: ARTS, SOCIAL SCIENCE AND HUMANITIES CLUSTER | D24: Filipino 2 (Filipino sa Sining at Disenyo) | E24: =B24&" - "&C24 -> ACADEMIC - ARTS, SOCIAL SCIENCE AND HUMANITIES CLUSTER | F24: 2 | G24: 2 | H24: =IF(AND(F24<>"",G24<>""),"11/12",IF(F24<>"",11,12)) -> 11/12 | L24: 18 | O24: =_xlfn.IFNA(IF(N24<>"",_xlfn.XLOOKUP(N24,$D$6:$D$138,$H$6:$H$138),""),"11/12") | Q24: =_xlfn.IFNA(IF(P24<>"",_xlfn.XLOOKUP(P24,$D$6:$D$138,$H$6:$H$138),""),"11/12") | R24: 18 | AB24: Academic Elective (All Other Electives) | AC24: ARTS, SOCIAL SCIENCE AND HUMANITIES CLUSTER | AD24: Social Sciences (Theory and Practice)
B25: ACADEMIC | C25: ARTS, SOCIAL SCIENCE AND HUMANITIES CLUSTER | D25: Introduction to Philosophy | E25: =B25&" - "&C25 -> ACADEMIC - ARTS, SOCIAL SCIENCE AND HUMANITIES CLUSTER | F25: 2 | G25: 2 | H25: =IF(AND(F25<>"",G25<>""),"11/12",IF(F25<>"",11,12)) -> 11/12 | L25: 19 | O25: =_xlfn.IFNA(IF(N25<>"",_xlfn.XLOOKUP(N25,$D$6:$D$138,$H$6:$H$138),""),"11/12") | Q25: =_xlfn.IFNA(IF(P25<>"",_xlfn.XLOOKUP(P25,$D$6:$D$138,$H$6:$H$138),""),"11/12") | R25: 19 | AB25: Academic Elective (All Other Electives) | AC25: BUSINESS AND ENTREPRENEURSHIP | AD25: Business 1 (Basic Accounting)
B26: ACADEMIC | C26: ARTS, SOCIAL SCIENCE AND HUMANITIES CLUSTER | D26: Malikhaing Pagsulat | E26: =B26&" - "&C26 -> ACADEMIC - ARTS, SOCIAL SCIENCE AND HUMANITIES CLUSTER | F26: 2 | G26: 2 | H26: =IF(AND(F26<>"",G26<>""),"11/12",IF(F26<>"",11,12)) -> 11/12 | L26: 20 | O26: =_xlfn.IFNA(IF(N26<>"",_xlfn.XLOOKUP(N26,$D$6:$D$138,$H$6:$H$138),""),"11/12") | Q26: =_xlfn.IFNA(IF(P26<>"",_xlfn.XLOOKUP(P26,$D$6:$D$138,$H$6:$H$138),""),"11/12") | R26: 20 | AB26: Academic Elective (All Other Electives) | AC26: BUSINESS AND ENTREPRENEURSHIP | AD26: Business 2 (Business Finance and Income Taxation)
B27: ACADEMIC | C27: ARTS, SOCIAL SCIENCE AND HUMANITIES CLUSTER | D27: Philippine Governance (Philippine Politics and Governance) | E27: =B27&" - "&C27 -> ACADEMIC - ARTS, SOCIAL SCIENCE AND HUMANITIES CLUSTER | F27: 2 | G27: 2 | H27: =IF(AND(F27<>"",G27<>""),"11/12",IF(F27<>"",11,12)) -> 11/12 | L27: 21 | O27: =_xlfn.IFNA(IF(N27<>"",_xlfn.XLOOKUP(N27,$D$6:$D$138,$H$6:$H$138),""),"11/12") | Q27: =_xlfn.IFNA(IF(P27<>"",_xlfn.XLOOKUP(P27,$D$6:$D$138,$H$6:$H$138),""),"11/12") | R27: 21 | AB27: Academic Elective (All Other Electives) | AC27: BUSINESS AND ENTREPRENEURSHIP | AD27: Business 3 (Business Economics)
B28: ACADEMIC | C28: ARTS, SOCIAL SCIENCE AND HUMANITIES CLUSTER | D28: Social Sciences (Theory and Practice) | E28: =B28&" - "&C28 -> ACADEMIC - ARTS, SOCIAL SCIENCE AND HUMANITIES CLUSTER | F28: 2 | G28: 2 | H28: =IF(AND(F28<>"",G28<>""),"11/12",IF(F28<>"",11,12)) -> 11/12 | L28: 22 | O28: =_xlfn.IFNA(IF(N28<>"",_xlfn.XLOOKUP(N28,$D$6:$D$138,$H$6:$H$138),""),"11/12") | Q28: =_xlfn.IFNA(IF(P28<>"",_xlfn.XLOOKUP(P28,$D$6:$D$138,$H$6:$H$138),""),"11/12") | R28: 22 | AB28: Academic Elective (All Other Electives) | AC28: BUSINESS AND ENTREPRENEURSHIP | AD28: Contemporary Marketing
B29: ACADEMIC | C29: BUSINESS AND ENTREPRENEURSHIP | D29: Business 1 (Basic Accounting) | E29: =B29&" - "&C29 -> ACADEMIC - BUSINESS AND ENTREPRENEURSHIP | F29: 2 | G29: 2 | H29: =IF(AND(F29<>"",G29<>""),"11/12",IF(F29<>"",11,12)) -> 11/12 | L29: 23 | O29: =_xlfn.IFNA(IF(N29<>"",_xlfn.XLOOKUP(N29,$D$6:$D$138,$H$6:$H$138),""),"11/12") | Q29: =_xlfn.IFNA(IF(P29<>"",_xlfn.XLOOKUP(P29,$D$6:$D$138,$H$6:$H$138),""),"11/12") | R29: 23 | AB29: Academic Elective (All Other Electives) | AC29: BUSINESS AND ENTREPRENEURSHIP | AD29: Entrepreneurship
B30: ACADEMIC | C30: BUSINESS AND ENTREPRENEURSHIP | D30: Business 2 (Business Finance and Income Taxation) | E30: =B30&" - "&C30 -> ACADEMIC - BUSINESS AND ENTREPRENEURSHIP | F30: 2 | G30: 2 | H30: =IF(AND(F30<>"",G30<>""),"11/12",IF(F30<>"",11,12)) -> 11/12 | L30: 24 | O30: =_xlfn.IFNA(IF(N30<>"",_xlfn.XLOOKUP(N30,$D$6:$D$138,$H$6:$H$138),""),"11/12") | Q30: =_xlfn.IFNA(IF(P30<>"",_xlfn.XLOOKUP(P30,$D$6:$D$138,$H$6:$H$138),""),"11/12") | R30: 24 | AB30: Academic Elective (All Other Electives) | AC30: BUSINESS AND ENTREPRENEURSHIP | AD30: Introduction to Organization and Management
B31: ACADEMIC | C31: BUSINESS AND ENTREPRENEURSHIP | D31: Business 3 (Business Economics) | E31: =B31&" - "&C31 -> ACADEMIC - BUSINESS AND ENTREPRENEURSHIP | F31: 2 | G31: 2 | H31: =IF(AND(F31<>"",G31<>""),"11/12",IF(F31<>"",11,12)) -> 11/12 | L31: 25 | O31: =_xlfn.IFNA(IF(N31<>"",_xlfn.XLOOKUP(N31,$D$6:$D$138,$H$6:$H$138),""),"11/12") | Q31: =_xlfn.IFNA(IF(P31<>"",_xlfn.XLOOKUP(P31,$D$6:$D$138,$H$6:$H$138),""),"11/12") | R31: 25 | AB31: Academic Elective (All Other Electives) | AC31: SCIENCE, TECHNOLOGY, ENGINEERING AND MATHEMATICS | AD31: Advanced Mathematics 1
B32: ACADEMIC | C32: BUSINESS AND ENTREPRENEURSHIP | D32: Contemporary Marketing | E32: =B32&" - "&C32 -> ACADEMIC - BUSINESS AND ENTREPRENEURSHIP | F32: 2 | G32: 2 | H32: =IF(AND(F32<>"",G32<>""),"11/12",IF(F32<>"",11,12)) -> 11/12 | L32: 26 | O32: =_xlfn.IFNA(IF(N32<>"",_xlfn.XLOOKUP(N32,$D$6:$D$138,$H$6:$H$138),""),"11/12") | Q32: =_xlfn.IFNA(IF(P32<>"",_xlfn.XLOOKUP(P32,$D$6:$D$138,$H$6:$H$138),""),"11/12") | R32: 26 | AB32: Academic Elective (All Other Electives) | AC32: SCIENCE, TECHNOLOGY, ENGINEERING AND MATHEMATICS | AD32: Advanced Mathematics 2
B33: ACADEMIC | C33: BUSINESS AND ENTREPRENEURSHIP | D33: Entrepreneurship | E33: =B33&" - "&C33 -> ACADEMIC - BUSINESS AND ENTREPRENEURSHIP | F33: 2 | G33: 2 | H33: =IF(AND(F33<>"",G33<>""),"11/12",IF(F33<>"",11,12)) -> 11/12 | L33: 27 | O33: =_xlfn.IFNA(IF(N33<>"",_xlfn.XLOOKUP(N33,$D$6:$D$138,$H$6:$H$138),""),"11/12") | Q33: =_xlfn.IFNA(IF(P33<>"",_xlfn.XLOOKUP(P33,$D$6:$D$138,$H$6:$H$138),""),"11/12") | R33: 27 | AB33: Academic Elective (All Other Electives) | AC33: SCIENCE, TECHNOLOGY, ENGINEERING AND MATHEMATICS | AD33: Biology 1
B34: ACADEMIC | C34: BUSINESS AND ENTREPRENEURSHIP | D34: Introduction to Organization and Management | E34: =B34&" - "&C34 -> ACADEMIC - BUSINESS AND ENTREPRENEURSHIP | F34: 2 | G34: 2 | H34: =IF(AND(F34<>"",G34<>""),"11/12",IF(F34<>"",11,12)) -> 11/12 | L34: 28 | O34: =_xlfn.IFNA(IF(N34<>"",_xlfn.XLOOKUP(N34,$D$6:$D$138,$H$6:$H$138),""),"11/12") | Q34: =_xlfn.IFNA(IF(P34<>"",_xlfn.XLOOKUP(P34,$D$6:$D$138,$H$6:$H$138),""),"11/12") | R34: 28 | AB34: Academic Elective (All Other Electives) | AC34: SCIENCE, TECHNOLOGY, ENGINEERING AND MATHEMATICS | AD34: Biology 2
B35: ACADEMIC | C35: SCIENCE, TECHNOLOGY, ENGINEERING AND MATHEMATICS | D35: Advanced Mathematics 1 | E35: =B35&" - "&C35 -> ACADEMIC - SCIENCE, TECHNOLOGY, ENGINEERING AND MATHEMATICS | G35: 2 | H35: =IF(AND(F35<>"",G35<>""),"11/12",IF(F35<>"",11,12)) -> 12 | L35: 29 | O35: =_xlfn.IFNA(IF(N35<>"",_xlfn.XLOOKUP(N35,$D$6:$D$138,$H$6:$H$138),""),"11/12") | Q35: =_xlfn.IFNA(IF(P35<>"",_xlfn.XLOOKUP(P35,$D$6:$D$138,$H$6:$H$138),""),"11/12") | R35: 29 | AB35: Academic Elective (All Other Electives) | AC35: SCIENCE, TECHNOLOGY, ENGINEERING AND MATHEMATICS | AD35: Biology 3
B36: ACADEMIC | C36: SCIENCE, TECHNOLOGY, ENGINEERING AND MATHEMATICS | D36: Advanced Mathematics 2 | E36: =B36&" - "&C36 -> ACADEMIC - SCIENCE, TECHNOLOGY, ENGINEERING AND MATHEMATICS | G36: 2 | H36: =IF(AND(F36<>"",G36<>""),"11/12",IF(F36<>"",11,12)) -> 12 | L36: 30 | O36: =_xlfn.IFNA(IF(N36<>"",_xlfn.XLOOKUP(N36,$D$6:$D$138,$H$6:$H$138),""),"11/12") | Q36: =_xlfn.IFNA(IF(P36<>"",_xlfn.XLOOKUP(P36,$D$6:$D$138,$H$6:$H$138),""),"11/12") | R36: 30 | AB36: Academic Elective (All Other Electives) | AC36: SCIENCE, TECHNOLOGY, ENGINEERING AND MATHEMATICS | AD36: Biology 4
B37: ACADEMIC | C37: SCIENCE, TECHNOLOGY, ENGINEERING AND MATHEMATICS | D37: Biology 1 | E37: =B37&" - "&C37 -> ACADEMIC - SCIENCE, TECHNOLOGY, ENGINEERING AND MATHEMATICS | F37: 2 | H37: =IF(AND(F37<>"",G37<>""),"11/12",IF(F37<>"",11,12)) -> 11 | L37: 31 | O37: =_xlfn.IFNA(IF(N37<>"",_xlfn.XLOOKUP(N37,$D$6:$D$138,$H$6:$H$138),""),"11/12") | Q37: =_xlfn.IFNA(IF(P37<>"",_xlfn.XLOOKUP(P37,$D$6:$D$138,$H$6:$H$138),""),"11/12") | R37: 31 | AB37: Academic Elective (All Other Electives) | AC37: SCIENCE, TECHNOLOGY, ENGINEERING AND MATHEMATICS | AD37: Chemistry 1
B38: ACADEMIC | C38: SCIENCE, TECHNOLOGY, ENGINEERING AND MATHEMATICS | D38: Biology 2 | E38: =B38&" - "&C38 -> ACADEMIC - SCIENCE, TECHNOLOGY, ENGINEERING AND MATHEMATICS | F38: 2 | H38: =IF(AND(F38<>"",G38<>""),"11/12",IF(F38<>"",11,12)) -> 11 | L38: 32 | O38: =_xlfn.IFNA(IF(N38<>"",_xlfn.XLOOKUP(N38,$D$6:$D$138,$H$6:$H$138),""),"11/12") | Q38: =_xlfn.IFNA(IF(P38<>"",_xlfn.XLOOKUP(P38,$D$6:$D$138,$H$6:$H$138),""),"11/12") | R38: 32 | AB38: Academic Elective (All Other Electives) | AC38: SCIENCE, TECHNOLOGY, ENGINEERING AND MATHEMATICS | AD38: Chemistry 2
B39: ACADEMIC | C39: SCIENCE, TECHNOLOGY, ENGINEERING AND MATHEMATICS | D39: Biology 3 | E39: =B39&" - "&C39 -> ACADEMIC - SCIENCE, TECHNOLOGY, ENGINEERING AND MATHEMATICS | G39: 2 | H39: =IF(AND(F39<>"",G39<>""),"11/12",IF(F39<>"",11,12)) -> 12 | L39: 33 | O39: =_xlfn.IFNA(IF(N39<>"",_xlfn.XLOOKUP(N39,$D$6:$D$138,$H$6:$H$138),""),"11/12") | Q39: =_xlfn.IFNA(IF(P39<>"",_xlfn.XLOOKUP(P39,$D$6:$D$138,$H$6:$H$138),""),"11/12") | R39: 33 | AB39: Academic Elective (All Other Electives) | AC39: SCIENCE, TECHNOLOGY, ENGINEERING AND MATHEMATICS | AD39: Chemistry 3
B40: ACADEMIC | C40: SCIENCE, TECHNOLOGY, ENGINEERING AND MATHEMATICS | D40: Biology 4 | E40: =B40&" - "&C40 -> ACADEMIC - SCIENCE, TECHNOLOGY, ENGINEERING AND MATHEMATICS | G40: 2 | H40: =IF(AND(F40<>"",G40<>""),"11/12",IF(F40<>"",11,12)) -> 12 | L40: 34 | O40: =_xlfn.IFNA(IF(N40<>"",_xlfn.XLOOKUP(N40,$D$6:$D$138,$H$6:$H$138),""),"11/12") | Q40: =_xlfn.IFNA(IF(P40<>"",_xlfn.XLOOKUP(P40,$D$6:$D$138,$H$6:$H$138),""),"11/12") | R40: 34 | AB40: Academic Elective (All Other Electives) | AC40: SCIENCE, TECHNOLOGY, ENGINEERING AND MATHEMATICS | AD40: Chemistry 4
...
